<robot name = "robot">
    <link name="0">
        <inertial>
            <origin xyz="0 0 0.8794305031691094" rpy="0 0 0"/>
            <mass value="1" />
            <inertia ixx="100" ixy="0" ixz="0" iyy="100" iyz="0" izz="100" />
        </inertial>
        <visual>
            <origin xyz="0 0 0.8794305031691094" rpy="0 0 0"/>
            <geometry>
                <box size="1.124661639662299 0.8437931983892348 1.503777981015163" />
            </geometry>
            <material name="Green">
                <color rgba="0 0 1.0 1.0"/>
            </material>
        </visual>
        <collision>
            <origin xyz="0 0 0.8794305031691094" rpy="0 0 0"/>
            <geometry>
                <box size="1.124661639662299 0.8437931983892348 1.503777981015163" />
            </geometry>
        </collision>
    </link>
    <joint name="0_1" type="revolute">
       <parent link="0"/>
       <child  link="1"/>
       <origin rpy="0 0 0" xyz="0.5623308198311495 0 0.4397152515845547" />
     <axis xyz="0 1 0"/>
       <limit effort="0.0" lower="-3.14159" upper="3.14159" velocity="0.0"/>
    </joint>
    <link name="1">
        <inertial>
            <origin xyz="0.10128998450496357 0 0.4397152515845547" rpy="0 0 0"/>
            <mass value="1" />
            <inertia ixx="100" ixy="0" ixz="0" iyy="100" iyz="0" izz="100" />
        </inertial>
        <visual>
            <origin xyz="0.10128998450496357 0 0.4397152515845547" rpy="0 0 0"/>
            <geometry>
                <box size="0.20257996900992714 1.4175572986767644 1.7588610063382188" />
            </geometry>
            <material name="Blue">
                <color rgba="0 0 1.0 1.0"/>
            </material>
        </visual>
        <collision>
            <origin xyz="0.10128998450496357 0 0.4397152515845547" rpy="0 0 0"/>
            <geometry>
                <box size="0.20257996900992714 1.4175572986767644 1.7588610063382188" />
            </geometry>
        </collision>
    </link>
    <joint name="1_2" type="revolute">
       <parent link="1"/>
       <child  link="2"/>
       <origin rpy="0 0 0" xyz="0.20257996900992714 0 0" />
     <axis xyz="0 1 0"/>
       <limit effort="0.0" lower="-3.14159" upper="3.14159" velocity="0.0"/>
    </joint>
    <link name="2">
        <inertial>
            <origin xyz="0.25350997344709103 0 0.3" rpy="0 0 0"/>
            <mass value="1" />
            <inertia ixx="100" ixy="0" ixz="0" iyy="100" iyz="0" izz="100" />
        </inertial>
        <visual>
            <origin xyz="0.25350997344709103 0 0.3" rpy="0 0 0"/>
            <geometry>
                <box size="0.5070199468941821 0.562062153297542 1.0548243073460521" />
            </geometry>
            <material name="Blue">
                <color rgba="0 0 1.0 1.0"/>
            </material>
        </visual>
        <collision>
            <origin xyz="0.25350997344709103 0 0.3" rpy="0 0 0"/>
            <geometry>
                <box size="0.5070199468941821 0.562062153297542 1.0548243073460521" />
            </geometry>
        </collision>
    </link>
    <joint name="2_3" type="revolute">
       <parent link="2"/>
       <child  link="3"/>
       <origin rpy="0 0 0" xyz="0.5070199468941821 0 0" />
     <axis xyz="0 1 0"/>
       <limit effort="0.0" lower="-3.14159" upper="3.14159" velocity="0.0"/>
    </joint>
    <link name="3">
        <inertial>
            <origin xyz="0.5257919103458006 0 0.3" rpy="0 0 0"/>
            <mass value="1" />
            <inertia ixx="100" ixy="0" ixz="0" iyy="100" iyz="0" izz="100" />
        </inertial>
        <visual>
            <origin xyz="0.5257919103458006 0 0.3" rpy="0 0 0"/>
            <geometry>
                <box size="1.0515838206916013 0.9900783166356182 1.741128196929069" />
            </geometry>
            <material name="Green">
                <color rgba="0 1.0 0 1.0"/>
            </material>
        </visual>
        <collision>
            <origin xyz="0.5257919103458006 0 0.3" rpy="0 0 0"/>
            <geometry>
                <box size="1.0515838206916013 0.9900783166356182 1.741128196929069" />
            </geometry>
        </collision>
    </link>
    <joint name="3_4" type="revolute">
       <parent link="3"/>
       <child  link="4"/>
       <origin rpy="0 0 0" xyz="1.0515838206916013 0 0" />
     <axis xyz="0 1 0"/>
       <limit effort="0.0" lower="-3.14159" upper="3.14159" velocity="0.0"/>
    </joint>
    <link name="4">
        <inertial>
            <origin xyz="0.459840334815382 0 0.3" rpy="0 0 0"/>
            <mass value="1" />
            <inertia ixx="100" ixy="0" ixz="0" iyy="100" iyz="0" izz="100" />
        </inertial>
        <visual>
            <origin xyz="0.459840334815382 0 0.3" rpy="0 0 0"/>
            <geometry>
                <box size="0.919680669630764 0.453303070246431 0.9199192077900877" />
            </geometry>
            <material name="Green">
                <color rgba="0 1.0 0 1.0"/>
            </material>
        </visual>
        <collision>
            <origin xyz="0.459840334815382 0 0.3" rpy="0 0 0"/>
            <geometry>
                <box size="0.919680669630764 0.453303070246431 0.9199192077900877" />
            </geometry>
        </collision>
    </link>
    <joint name="4_5" type="revolute">
       <parent link="4"/>
       <child  link="5"/>
       <origin rpy="0 0 0" xyz="0.919680669630764 0 0" />
     <axis xyz="0 1 0"/>
       <limit effort="0.0" lower="-3.14159" upper="3.14159" velocity="0.0"/>
    </joint>
    <link name="5">
        <inertial>
            <origin xyz="0.39932157703063786 0 0.3" rpy="0 0 0"/>
            <mass value="1" />
            <inertia ixx="100" ixy="0" ixz="0" iyy="100" iyz="0" izz="100" />
        </inertial>
        <visual>
            <origin xyz="0.39932157703063786 0 0.3" rpy="0 0 0"/>
            <geometry>
                <box size="0.7986431540612757 1.6249110410311163 0.8910293790451747" />
            </geometry>
            <material name="Green">
                <color rgba="0 1.0 0 1.0"/>
            </material>
        </visual>
        <collision>
            <origin xyz="0.39932157703063786 0 0.3" rpy="0 0 0"/>
            <geometry>
                <box size="0.7986431540612757 1.6249110410311163 0.8910293790451747" />
            </geometry>
        </collision>
    </link>
    <joint name="5_6" type="revolute">
       <parent link="5"/>
       <child  link="6"/>
       <origin rpy="0 0 0" xyz="0.7986431540612757 0 0" />
     <axis xyz="0 1 0"/>
       <limit effort="0.0" lower="-3.14159" upper="3.14159" velocity="0.0"/>
    </joint>
    <link name="6">
        <inertial>
            <origin xyz="0.06189112169548606 0 0.3" rpy="0 0 0"/>
            <mass value="1" />
            <inertia ixx="100" ixy="0" ixz="0" iyy="100" iyz="0" izz="100" />
        </inertial>
        <visual>
            <origin xyz="0.06189112169548606 0 0.3" rpy="0 0 0"/>
            <geometry>
                <box size="0.12378224339097212 1.1183044910094482 0.4618571616733092" />
            </geometry>
            <material name="Green">
                <color rgba="0 1.0 0 1.0"/>
            </material>
        </visual>
        <collision>
            <origin xyz="0.06189112169548606 0 0.3" rpy="0 0 0"/>
            <geometry>
                <box size="0.12378224339097212 1.1183044910094482 0.4618571616733092" />
            </geometry>
        </collision>
    </link>
</robot>